Workbook

Sheet 00_دليل الاستخدام
A1: Trust Drive (TD) — ملف تشغيل قطع الغيار
A3: الغرض | B3: هذا الملف هو (مصدر الحقيقة الوحيد) لبيانات القطع والأسعار والتوفر. الموقع يقرأ منه ولا يخزّن أسعاراً بشكل مستقل.
A4: كيف يعمل | B4: ترفع الملف على Google Sheets أو OneDrive → المبرمج يربطه بالموقع عبر مزامنة كل 15 دقيقة أو زر (تحديث الآن).
A6: الخلايا الصفراء | B6: خلايا إدخال يدوي — أنت أو موظف المشتريات يعبّئها.
A7: الخلايا البيضاء | B7: معادلات محسوبة تلقائياً — لا تعدّلها.
A9: ترتيب العمل اليومي | B9: 1) حدّث ورقة 04 (التسعير والمخزون) من المناديب صباحاً.
B10: 2) راجع ورقة 08 (الطلب المفقود) — كل بحث فشل هو فرصة بيع ضائعة.
B11: 3) راجع ورقة 09 (لوحة التحليلات) أسبوعياً.
A13: الأوراق | B13: 01 الإعدادات · 02 كتالوج القطع · 03 المناديب · 04 التسعير والمخزون · 05 مدن التوصيل
B14: 06 حاسبة التوفر (المحرك) · 07 سجل الطلبات · 08 الطلب المفقود · 09 لوحة التحليلات
A16: ملاحظة مهمة | B16: البيانات الموجودة حالياً هي أمثلة توضيحية للصيغة المطلوبة فقط — استبدلها ببياناتك.

Sheet 01_الإعدادات
A1: الإعدادات العامة للمنصة
A3: المتغير | B3: القيمة | C3: الوصف / الاستخدام
A4: نسبة ضريبة القيمة المضافة | B4: 0.15 | C4: تُضاف على سعر البيع النهائي
A5: هامش الربح الافتراضي | B5: 0.35 | C5: يُستخدم إذا لم يُحدد هامش خاص للقطعة
A6: أيام التجهيز داخل الرياض | B6: 1 | C6: من الدفع حتى خروج الشحنة (المخزون متوفر)
A7: أيام التوريد من المندوب | B7: 1 | C7: إذا كانت القطعة عند المندوب وليست بمستودعنا
A8: ساعة قطع الطلبات | B8: 14 | C8: الطلب بعد هذه الساعة يُحتسب من اليوم التالي
A9: حد الثقة العالية | B9: 0.85 | C9: أعلى منه = وعد مضمون (أخضر)
A10: حد الثقة المتوسطة | B10: 0.65 | C10: بينهما = وعد تقديري (أصفر) · أقل = طلب خاص (رمادي)
A11: قيمة تعويض تأخر الوعد (ريال) | B11: 50 | C11: رصيد يُمنح للعميل تلقائياً عند الإخلال بالوعد
A12: سعر ساعة العمل (ريال) | B12: 120 | C12: أجرة اليد في المركز — أساس حساب تكلفة التركيب
A13: خصم التركيب عبر الموقع | B13: 0.1 | C13: خصم على أجرة اليد لمن يشتري القطعة من الموقع ويركّبها لدينا
A15: الخلايا الصفراء = إدخال يدوي. غيّر القيم هنا وستتحدث كل الأوراق تلقائياً.

Sheet 02_كتالوج القطع
A1: كتالوج القطع — السجل الرئيسي
A3: كود القطعة (SKU) | B3: رقم القطعة الأصلي (OEM) | C3: اسم القطعة (عربي) | D3: Part Name (EN) | E3: الفئة | F3: الماركة | G3: الموديلات المتوافقة | H3: نطاق السنوات | I3: مستوى الجودة | J3: الضمان (شهر) | K3: قابلة للتركيب بالمركز | L3: الحالة
A4: TD-BRK-0001 | B4: 04465-33471 | C4: فحمات فرامل أمامية | D4: Front Brake Pads | E4: فرامل | F4: تويوتا | G4: كامري | H4: 2018-2024 | I4: وكالة | J4: 12 | K4: نعم | L4: نشط
A5: TD-BRK-0002 | B5: AD-0451 | C5: فحمات فرامل أمامية | D5: Front Brake Pads | E5: فرامل | F5: تويوتا | G5: كامري | H5: 2018-2024 | I5: بديل معتمد | J5: 6 | K5: نعم | L5: نشط
A6: TD-FLT-0010 | B6: 90915-YZZD4 | C6: فلتر زيت | D6: Oil Filter | E6: فلاتر | F6: تويوتا | G6: كامري / كورولا | H6: 2015-2024 | I6: وكالة | J6: 6 | K6: نعم | L6: نشط
A7: TD-BAT-0020 | B7: AGM-70AH | C7: بطارية 70 أمبير | D7: Battery 70AH | E7: كهرباء | F7: متعدد | G7: متعدد | H7: الكل | I7: بديل معتمد | J7: 24 | K7: نعم | L7: نشط
A8: TD-SUS-0031 | B8: 48510-0K120 | C8: مساعد أمامي | D8: Front Shock Absorber | E8: عفشة | F8: تويوتا | G8: هايلكس | H8: 2016-2023 | I8: وكالة | J8: 12 | K8: نعم | L8: نشط
A9: TD-COL-0044 | B9: 16400-0P260 | C9: ردياتير | D9: Radiator | E9: تبريد | F9: تويوتا | G9: لاندكروزر | H9: 2016-2021 | I9: بديل معتمد | J9: 12 | K9: نعم | L9: نشط
A10: TD-ELC-0055 | B10: 28100-0T030 | C10: دينمو تشغيل (سلف) | D10: Starter Motor | E10: كهرباء | F10: تويوتا | G10: كورولا | H10: 2014-2019 | I10: تجاري | J10: 3 | K10: نعم | L10: نشط
A11: TD-BDY-0066 | B11: 53101-06923 | C11: صدام أمامي | D11: Front Bumper | E11: هيكل | F11: تويوتا | G11: كامري | H11: 2021-2024 | I11: بديل معتمد | J11: 3 | K11: لا | L11: نشط
A13: مستوى الجودة: وكالة / بديل معتمد / تجاري / مستعمل مفحوص — هذا العمود هو أساس (بطاقة الشفافية) في الموقع.

Sheet 03_المناديب
A1: المناديب والموردون — الرياض
A3: كود المورد | B3: اسم المورد / المندوب | C3: المنطقة | D3: الجوال | E3: التخصص | F3: نسبة الالتزام % | G3: وقت التوريد (ساعة) | H3: شروط الدفع | I3: التقييم (1-5)
A4: SUP-01 | B4: مؤسسة الشميسي لقطع الغيار | C4: الشميسي | D4: 05xxxxxxxx | E4: تويوتا وكالة | F4: 0.95 | G4: 4 | H4: آجل 30 يوم | I4: 5
A5: SUP-02 | B5: مندوب الغزالي - أبو محمد | C5: الغزالي | D5: 05xxxxxxxx | E5: بديل معتمد | F5: 0.88 | G5: 6 | H5: كاش | I5: 4
A6: SUP-03 | B6: شركة الصناعية للبطاريات | C6: الصناعية | D6: 05xxxxxxxx | E6: بطاريات وكهرباء | F6: 0.92 | G6: 8 | H6: آجل 15 يوم | I6: 4
A7: SUP-04 | B7: مخزن TD الرئيسي | C7: المركز | D7: - | E7: مخزون داخلي | F7: 1 | G7: 0 | H7: - | I7: 5
A8: SUP-05 | B8: مورد الهيكل - المصانع | C8: المصانع | D8: 05xxxxxxxx | E8: هيكل وصدامات | F8: 0.75 | G8: 24 | H8: كاش | I8: 3
A10: نسبة الالتزام = عدد الطلبات التي وفّرها في الوقت ÷ إجمالي طلباته. حدّثها شهرياً — هي أهم رقم في الملف.

Sheet 04_التسعير والمخزون
A1: التسعير والمخزون — يُحدَّث يومياً
A3: كود القطعة (SKU) | B3: اسم القطعة | C3: كود المورد | D3: سعر التكلفة | E3: هامش الربح | F3: سعر البيع قبل الضريبة | G3: سعر البيع شامل الضريبة | H3: الكمية بمخزن TD | I3: الكمية عند المندوب | J3: آخر تحديث | K3: متاح للبيع
A4: TD-BRK-0001 | B4: =IFERROR(INDEX('02_كتالوج القطع'!$C$4:$C$200,MATCH($A4,'02_كتالوج القطع'!$A$4:$A$200,0)),"غير موجود") -> فحمات فرامل أمامية | C4: SUP-01 | D4: 210 | E4: 0.35 | F4: =$D4*(1+IF($E4="",01_الإعدادات!$B$5,$E4)) -> 283.5 | G4: =$F4*(1+01_الإعدادات!$B$4) -> 326.025 | H4: 6 | I4: 12 | J4: 2026-07-28 | K4: =IF(($H4+$I4)>0,"نعم","لا") -> نعم
A5: TD-BRK-0002 | B5: =IFERROR(INDEX('02_كتالوج القطع'!$C$4:$C$200,MATCH($A5,'02_كتالوج القطع'!$A$4:$A$200,0)),"غير موجود") -> فحمات فرامل أمامية | C5: SUP-02 | D5: 120 | E5: 0.45 | F5: =$D5*(1+IF($E5="",01_الإعدادات!$B$5,$E5)) -> 174 | G5: =$F5*(1+01_الإعدادات!$B$4) -> 200.1 | H5: 10 | I5: 25 | J5: 2026-07-28 | K5: =IF(($H5+$I5)>0,"نعم","لا") -> نعم
A6: TD-FLT-0010 | B6: =IFERROR(INDEX('02_كتالوج القطع'!$C$4:$C$200,MATCH($A6,'02_كتالوج القطع'!$A$4:$A$200,0)),"غير موجود") -> فلتر زيت | C6: SUP-01 | D6: 22 | E6: 0.6 | F6: =$D6*(1+IF($E6="",01_الإعدادات!$B$5,$E6)) -> 35.2 | G6: =$F6*(1+01_الإعدادات!$B$4) -> 40.48 | H6: 40 | I6: 100 | J6: 2026-07-28 | K6: =IF(($H6+$I6)>0,"نعم","لا") -> نعم
A7: TD-BAT-0020 | B7: =IFERROR(INDEX('02_كتالوج القطع'!$C$4:$C$200,MATCH($A7,'02_كتالوج القطع'!$A$4:$A$200,0)),"غير موجود") -> بطارية 70 أمبير | C7: SUP-03 | D7: 285 | E7: 0.3 | F7: =$D7*(1+IF($E7="",01_الإعدادات!$B$5,$E7)) -> 370.5 | G7: =$F7*(1+01_الإعدادات!$B$4) -> 426.075 | H7: 8 | I7: 30 | J7: 2026-07-28 | K7: =IF(($H7+$I7)>0,"نعم","لا") -> نعم
A8: TD-SUS-0031 | B8: =IFERROR(INDEX('02_كتالوج القطع'!$C$4:$C$200,MATCH($A8,'02_كتالوج القطع'!$A$4:$A$200,0)),"غير موجود") -> مساعد أمامي | C8: SUP-01 | D8: 340 | E8: 0.35 | F8: =$D8*(1+IF($E8="",01_الإعدادات!$B$5,$E8)) -> 459 | G8: =$F8*(1+01_الإعدادات!$B$4) -> 527.85 | H8: 0 | I8: 6 | J8: 2026-07-28 | K8: =IF(($H8+$I8)>0,"نعم","لا") -> نعم
A9: TD-COL-0044 | B9: =IFERROR(INDEX('02_كتالوج القطع'!$C$4:$C$200,MATCH($A9,'02_كتالوج القطع'!$A$4:$A$200,0)),"غير موجود") -> ردياتير | C9: SUP-02 | D9: 480 | E9: 0.32 | F9: =$D9*(1+IF($E9="",01_الإعدادات!$B$5,$E9)) -> 633.6 | G9: =$F9*(1+01_الإعدادات!$B$4) -> 728.64 | H9: 2 | I9: 4 | J9: 2026-07-28 | K9: =IF(($H9+$I9)>0,"نعم","لا") -> نعم
A10: TD-ELC-0055 | B10: =IFERROR(INDEX('02_كتالوج القطع'!$C$4:$C$200,MATCH($A10,'02_كتالوج القطع'!$A$4:$A$200,0)),"غير موجود") -> دينمو تشغيل (سلف) | C10: SUP-02 | D10: 390 | E10: 0.4 | F10: =$D10*(1+IF($E10="",01_الإعدادات!$B$5,$E10)) -> 546 | G10: =$F10*(1+01_الإعدادات!$B$4) -> 627.9 | H10: 0 | I10: 3 | J10: 2026-07-28 | K10: =IF(($H10+$I10)>0,"نعم","لا") -> نعم
A11: TD-BDY-0066 | B11: =IFERROR(INDEX('02_كتالوج القطع'!$C$4:$C$200,MATCH($A11,'02_كتالوج القطع'!$A$4:$A$200,0)),"غير موجود") -> صدام أمامي | C11: SUP-05 | D11: 620 | E11: 0.28 | F11: =$D11*(1+IF($E11="",01_الإعدادات!$B$5,$E11)) -> 793.6 | G11: =$F11*(1+01_الإعدادات!$B$4) -> 912.64 | H11: 0 | I11: 1 | J11: 2026-07-28 | K11: =IF(($H11+$I11)>0,"نعم","لا") -> نعم
A13: سعر البيع محسوب تلقائياً = التكلفة × (1+الهامش) ثم + الضريبة. عدّل التكلفة أو الهامش فقط.

Sheet 05_مدن التوصيل
A1: مدن التوصيل واتفاقية مستوى الخدمة (SLA) — المركز في حائل
A3: المدينة | B3: المنطقة | C3: أيام الشحن (أدنى) | D3: أيام الشحن (أعلى) | E3: تكلفة الشحن | F3: شركة الشحن | G3: توصيل بنفس اليوم | H3: معامل الثقة
A4: حائل | B4: الشمالية | C4: 0 | D4: 1 | E4: 0 | F4: مندوب TD | G4: نعم | H4: 1
A5: القصيم | B5: الوسطى | C5: 1 | D5: 1 | E5: 25 | F5: سمسا | G5: لا | H5: 0.96
A6: الجوف | B6: الشمالية | C6: 1 | D6: 2 | E6: 35 | F6: أرامكس | G6: لا | H6: 0.91
A7: تبوك | B7: الشمالية | C7: 1 | D7: 2 | E7: 40 | F7: أرامكس | G7: لا | H7: 0.9
A8: الرياض | B8: الوسطى | C8: 1 | D8: 2 | E8: 30 | F8: سمسا | G8: لا | H8: 0.94
A9: المدينة المنورة | B9: الغربية | C9: 1 | D9: 2 | E9: 35 | F9: سمسا | G9: لا | H9: 0.92
A10: جدة | B10: الغربية | C10: 2 | D10: 3 | E10: 35 | F10: سمسا | G10: لا | H10: 0.9
A11: مكة المكرمة | B11: الغربية | C11: 2 | D11: 3 | E11: 40 | F11: سمسا | G11: لا | H11: 0.88
A12: الدمام | B12: الشرقية | C12: 2 | D12: 3 | E12: 35 | F12: سمسا | G12: لا | H12: 0.9
A13: أبها | B13: الجنوبية | C13: 3 | D13: 4 | E13: 45 | F13: أرامكس | G13: لا | H13: 0.84
A14: جازان | B14: الجنوبية | C14: 3 | D14: 4 | E14: 50 | F14: أرامكس | G14: لا | H14: 0.82
A16: معامل الثقة = نسبة الشحنات التي وصلت في الموعد لهذه المدينة تاريخياً. ابدأ بتقدير ثم صحّحه بالبيانات الفعلية من ورقة 07.

Sheet 06_حاسبة التوفر
A1: محرك التوفر — Availability Promise Engine
A2: هذه هي المعادلة التي سينفّذها المبرمج في الموقع. جرّبها هنا يدوياً أولاً.
A4: المدخلات
A5: كود القطعة (SKU) | B5: TD-SUS-0031
A6: مدينة العميل | B6: جدة
A8: المخرجات المحسوبة
A10: اسم القطعة | B10: =IFERROR(INDEX('02_كتالوج القطع'!$C$4:$C$200,MATCH($B$5,'02_كتالوج القطع'!$A$4:$A$200,0)),"غير موجود") -> مساعد أمامي | C10: من الكتالوج
A11: مستوى الجودة | B11: =IFERROR(INDEX('02_كتالوج القطع'!$I$4:$I$200,MATCH($B$5,'02_كتالوج القطع'!$A$4:$A$200,0)),"-") -> وكالة | C11: وكالة / بديل / تجاري
A12: الضمان (شهر) | B12: =IFERROR(INDEX('02_كتالوج القطع'!$J$4:$J$200,MATCH($B$5,'02_كتالوج القطع'!$A$4:$A$200,0)),0) -> 12 | C12: يُعرض للعميل
A13: سعر القطعة شامل الضريبة | B13: =IFERROR(INDEX('04_التسعير والمخزون'!$G$4:$G$200,MATCH($B$5,'04_التسعير والمخزون'!$A$4:$A$200,0)),0) -> 527.85 | C13: من ورقة التسعير
A14: تكلفة الشحن للمدينة | B14: =IFERROR(INDEX('05_مدن التوصيل'!$E$4:$E$100,MATCH($B$6,'05_مدن التوصيل'!$A$4:$A$100,0)),0) -> 35 | C14: من جدول المدن
A15: الإجمالي النهائي للعميل | B15: =$B$13+$B$14 -> 562.85 | C15: السعر الذي يُعرض في الموقع
A16: الكمية بمخزن TD | B16: =IFERROR(INDEX('04_التسعير والمخزون'!$H$4:$H$200,MATCH($B$5,'04_التسعير والمخزون'!$A$4:$A$200,0)),0) -> 0 | C16: متوفر فوراً
A17: الكمية عند المندوب | B17: =IFERROR(INDEX('04_التسعير والمخزون'!$I$4:$I$200,MATCH($B$5,'04_التسعير والمخزون'!$A$4:$A$200,0)),0) -> 6 | C17: يحتاج توريد
A18: نسبة التزام المورد | B18: =IFERROR(INDEX(03_المناديب!$F$4:$F$100,MATCH(INDEX('04_التسعير والمخزون'!$C$4:$C$200,MATCH($B$5,'04_التسعير والمخزون'!$A$4:$A$200,0)),03_المناديب!$A$4:$A$100,0)),0) -> 0.95 | C18: العامل الأهم في الثقة
A19: معامل ثقة المدينة | B19: =IFERROR(INDEX('05_مدن التوصيل'!$H$4:$H$100,MATCH($B$6,'05_مدن التوصيل'!$A$4:$A$100,0)),0) -> 0.9 | C19: أداء الشحن التاريخي
A20: أيام التجهيز | B20: =IF($B$16>0,01_الإعدادات!$B$6,IF($B$17>0,01_الإعدادات!$B$6+01_الإعدادات!$B$7,5)) -> 2 | C20: 0 مخزون داخلي · +1 من المندوب · 5 طلب خاص
A21: أيام الشحن (أعلى تقدير) | B21: =IFERROR(INDEX('05_مدن التوصيل'!$D$4:$D$100,MATCH($B$6,'05_مدن التوصيل'!$A$4:$A$100,0)),7) -> 3 | C21: من جدول المدن
A22: إجمالي أيام التسليم المتوقع | B22: =$B$20+$B$21 -> 5 | C22: الوعد المعروض للعميل
A23: نسبة الثقة في الوعد | B23: =IF($B$16>0,0.99*$B$19,IF($B$17>0,$B$18*$B$19,0.5*$B$19)) -> 0.855 | C23: المخزون الداخلي = ثقة شبه مؤكدة
A25: الرسالة المعروضة للعميل
A26: النص التلقائي | B26: =IF($B$23>=01_الإعدادات!$B$9,"مضمون الوصول خلال "&$B$22&" أيام — وإلا نعوّضك",IF($B$23>=01_الإعدادات!$B$10,"متوقع الوصول خلال "&$B$22&" أيام بإذن الله","طلب خاص — نؤكد لك التوفر خلال 24 ساعة قبل السحب من بطاقتك")) -> مضمون الوصول خلال 5 أيام — وإلا نعوّضك
A28: منطق الألوان في الموقع: ثقة ≥85% = أخضر (وعد مضمون) · 65-85% = أصفر (وعد تقديري) · <65% = رمادي (طلب خاص، لا نسحب المبلغ إلا بعد التأكيد).

Sheet 07_سجل الطلبات
A1: سجل الطلبات — يُصدَّر من الموقع تلقائياً
A3: رقم الطلب | B3: التاريخ | C3: كود القطعة | D3: الكمية | E3: المدينة | F3: سعر البيع للوحدة | G3: التكلفة للوحدة | H3: إجمالي البيع | I3: إجمالي الربح | J3: الوعد (يوم) | K3: التسليم الفعلي (يوم) | L3: التزمنا بالوعد؟ | M3: حالة الطلب | N3: قناة الطلب
A4: TD-1001 | B4: 2026-07-01 | C4: TD-BRK-0001 | D4: 1 | E4: الرياض | F4: 326.03 | G4: 210 | H4: =$D4*$F4 -> 326.03 | I4: =$D4*($F4/(1+01_الإعدادات!$B$4)-$G4) -> 73.504348 | J4: 1 | K4: 1 | L4: =IF($K4<=$J4,"نعم","لا") -> نعم | M4: مكتمل | N4: موقع
A5: TD-1002 | B5: 2026-07-02 | C5: TD-FLT-0010 | D5: 4 | E5: جدة | F5: 40.48 | G5: 22 | H5: =$D5*$F5 -> 161.92 | I5: =$D5*($F5/(1+01_الإعدادات!$B$4)-$G5) -> 52.8 | J5: 3 | K5: 3 | L5: =IF($K5<=$J5,"نعم","لا") -> نعم | M5: مكتمل | N5: موقع
A6: TD-1003 | B6: 2026-07-04 | C6: TD-BAT-0020 | D6: 1 | E6: الدمام | F6: 426.08 | G6: 285 | H6: =$D6*$F6 -> 426.08 | I6: =$D6*($F6/(1+01_الإعدادات!$B$4)-$G6) -> 85.504348 | J6: 3 | K6: 4 | L6: =IF($K6<=$J6,"نعم","لا") -> لا | M6: مكتمل | N6: تطبيق
A7: TD-1004 | B7: 2026-07-06 | C7: TD-SUS-0031 | D7: 2 | E7: أبها | F7: 527.85 | G7: 340 | H7: =$D7*$F7 -> 1055.7 | I7: =$D7*($F7/(1+01_الإعدادات!$B$4)-$G7) -> 238 | J7: 5 | K7: 6 | L7: =IF($K7<=$J7,"نعم","لا") -> لا | M7: مكتمل | N7: موقع
A8: TD-1005 | B8: 2026-07-09 | C8: TD-COL-0044 | D8: 1 | E8: الرياض | F8: 728.64 | G8: 480 | H8: =$D8*$F8 -> 728.64 | I8: =$D8*($F8/(1+01_الإعدادات!$B$4)-$G8) -> 153.6 | J8: 2 | K8: 2 | L8: =IF($K8<=$J8,"نعم","لا") -> نعم | M8: مكتمل | N8: واتساب
A9: TD-1006 | B9: 2026-07-12 | C9: TD-BRK-0002 | D9: 3 | E9: القصيم | F9: 200.1 | G9: 120 | H9: =$D9*$F9 -> 600.3 | I9: =$D9*($F9/(1+01_الإعدادات!$B$4)-$G9) -> 162 | J9: 3 | K9: 3 | L9: =IF($K9<=$J9,"نعم","لا") -> نعم | M9: مكتمل | N9: موقع
A10: TD-1007 | B10: 2026-07-15 | C10: TD-ELC-0055 | D10: 1 | E10: جدة | F10: 627.9 | G10: 390 | H10: =$D10*$F10 -> 627.9 | I10: =$D10*($F10/(1+01_الإعدادات!$B$4)-$G10) -> 156 | J10: 4 | K10: 7 | L10: =IF($K10<=$J10,"نعم","لا") -> لا | M10: مكتمل | N10: موقع
A11: TD-1008 | B11: 2026-07-18 | C11: TD-BDY-0066 | D11: 1 | E11: مكة المكرمة | F11: 912.13 | G11: 620 | H11: =$D11*$F11 -> 912.13 | I11: =$D11*($F11/(1+01_الإعدادات!$B$4)-$G11) -> 173.15652 | J11: 6 | K11: 6 | L11: =IF($K11<=$J11,"نعم","لا") -> نعم | M11: مكتمل | N11: تطبيق
A12: TD-1009 | B12: 2026-07-20 | C12: TD-FLT-0010 | D12: 10 | E12: الرياض | F12: 40.48 | G12: 22 | H12: =$D12*$F12 -> 404.8 | I12: =$D12*($F12/(1+01_الإعدادات!$B$4)-$G12) -> 132 | J12: 1 | K12: 1 | L12: =IF($K12<=$J12,"نعم","لا") -> نعم | M12: مكتمل | N12: مركز
A13: TD-1010 | B13: 2026-07-24 | C13: TD-BRK-0001 | D13: 2 | E13: الرياض | F13: 326.03 | G13: 210 | H13: =$D13*$F13 -> 652.06 | I13: =$D13*($F13/(1+01_الإعدادات!$B$4)-$G13) -> 147.0087 | J13: 1 | K13: 1 | L13: =IF($K13<=$J13,"نعم","لا") -> نعم | M13: مكتمل | N13: موقع

Sheet 08_الطلب المفقود
A1: سجل الطلب المفقود — كل بحث لم يجد نتيجة (كنز البيانات)
A2: هذه الورقة هي التي ستحدد لك بعد سنتين أي قطعة تصنّعها. لا تهملها.
A4: التاريخ | B4: نص البحث كما كتبه العميل | C4: رقم OEM (إن وُجد) | D4: الماركة | E4: الموديل | F4: السنة | G4: المدينة | H4: عدد مرات البحث | I4: سبب عدم التوفر | J4: هل وفّرناها لاحقاً؟ | K4: الطلب المقدّر شهرياً
A5: 2026-07-03 | B5: مساعد خلفي هايلكس 2019 | C5: 48531-0K600 | D5: تويوتا | E5: هايلكس | F5: 2019 | G5: الرياض | H5: 14 | I5: غير متوفر بالسوق | J5: نعم | K5: 18
A6: 2026-07-05 | B6: كمبروسر مكيف لاندكروزر | C6: 88320-60800 | D6: تويوتا | E6: لاندكروزر | F6: 2018 | G6: جدة | H6: 9 | I6: سعر مرتفع جداً | J6: لا | K6: 12
A7: 2026-07-08 | B7: فحمات خلفية كامري 2022 | C7: 04466-33210 | D7: تويوتا | E7: كامري | F7: 2022 | G7: الدمام | H7: 22 | I7: غير مدرج بالكتالوج | J7: نعم | K7: 30
A8: 2026-07-11 | B8: طرمبة بنزين النترا | C8: 31111-2H000 | D8: هيونداي | E8: النترا | F8: 2020 | G8: الرياض | H8: 11 | I8: ماركة غير مغطاة | J8: لا | K8: 15
A9: 2026-07-14 | B9: دعامية مقص سوناتا | C9: 54551-3S000 | D9: هيونداي | E9: سوناتا | F9: 2019 | G9: القصيم | H9: 8 | I9: ماركة غير مغطاة | J9: لا | K9: 10
A10: 2026-07-17 | B10: رديتر مكيف اكورد | C10: 80100-T2F-A01 | D10: هوندا | E10: أكورد | F10: 2021 | G10: جدة | H10: 7 | I10: ماركة غير مغطاة | J10: لا | K10: 9
A11: 2026-07-21 | B11: مساعد امامي هايلكس | C11: 48510-0K680 | D11: تويوتا | E11: هايلكس | F11: 2021 | G11: أبها | H11: 16 | I11: نفاد المخزون | J11: نعم | K11: 20
A12: 2026-07-25 | B12: فحمات فرامل هايلكس | C12: 04465-0K420 | D12: تويوتا | E12: هايلكس | F12: 2020 | G12: الرياض | H12: 19 | I12: نفاد المخزون | J12: نعم | K12: 25
A14: المبرمج يسجّل هنا تلقائياً: كل بحث انتهى بـ (لا توجد نتائج) أو (غير متوفر) + كل ضغطة على زر (أبلغني عند التوفر).

Sheet 09_لوحة التحليلات
A1: لوحة التحليلات — قرارات الشراء والتصنيع
A3: أولاً: مؤشرات الأداء العامة
A4: إجمالي المبيعات (ريال) | B4: =SUM('07_سجل الطلبات'!$H$4:$H$1000) -> 5895.56
A5: إجمالي الربح (ريال) | B5: =SUM('07_سجل الطلبات'!$I$4:$I$1000) -> 1373.5739
A6: عدد الطلبات | B6: =COUNTA('07_سجل الطلبات'!$A$4:$A$1000) -> 10
A7: متوسط قيمة الطلب | B7: =IFERROR($B$4/$B$6,0) -> 589.556
A8: نسبة الالتزام بالوعد | B8: =IFERROR(COUNTIF('07_سجل الطلبات'!$L$4:$L$1000,"نعم")/$B$6,0) -> 0.7
A9: نسبة الربح من المبيعات | B9: =IFERROR($B$5/$B$4,0) -> 0.23298447
A12: ثانياً: أداء القطع + درجة أولوية التصنيع
A13: كود القطعة | B13: اسم القطعة | C13: الكمية المباعة | D13: إجمالي المبيعات | E13: إجمالي الربح | F13: الطلب المفقود شهرياً | G13: درجة أولوية التصنيع
A14: TD-BRK-0001 | B14: =IFERROR(INDEX('02_كتالوج القطع'!$C$4:$C$200,MATCH($A14,'02_كتالوج القطع'!$A$4:$A$200,0)),"-") -> فحمات فرامل أمامية | C14: =SUMIF('07_سجل الطلبات'!$C$4:$C$1000,$A14,'07_سجل الطلبات'!$D$4:$D$1000) -> 3 | D14: =SUMIF('07_سجل الطلبات'!$C$4:$C$1000,$A14,'07_سجل الطلبات'!$H$4:$H$1000) -> 978.09 | E14: =SUMIF('07_سجل الطلبات'!$C$4:$C$1000,$A14,'07_سجل الطلبات'!$I$4:$I$1000) -> 220.51304 | F14: =SUMIF('08_الطلب المفقود'!$C$5:$C$1000,IFERROR(INDEX('02_كتالوج القطع'!$B$4:$B$200,MATCH($A14,'02_كتالوج القطع'!$A$4:$A$200,0)),""),'08_الطلب المفقود'!$K$5:$K$1000) -> 0 | G14: =ROUND(($C14*0.4)+($F14*0.4)+(IFERROR($E14/$D14,0)*100*0.2),1) -> 5.7
A15: TD-BRK-0002 | B15: =IFERROR(INDEX('02_كتالوج القطع'!$C$4:$C$200,MATCH($A15,'02_كتالوج القطع'!$A$4:$A$200,0)),"-") -> فحمات فرامل أمامية | C15: =SUMIF('07_سجل الطلبات'!$C$4:$C$1000,$A15,'07_سجل الطلبات'!$D$4:$D$1000) -> 3 | D15: =SUMIF('07_سجل الطلبات'!$C$4:$C$1000,$A15,'07_سجل الطلبات'!$H$4:$H$1000) -> 600.3 | E15: =SUMIF('07_سجل الطلبات'!$C$4:$C$1000,$A15,'07_سجل الطلبات'!$I$4:$I$1000) -> 162 | F15: =SUMIF('08_الطلب المفقود'!$C$5:$C$1000,IFERROR(INDEX('02_كتالوج القطع'!$B$4:$B$200,MATCH($A15,'02_كتالوج القطع'!$A$4:$A$200,0)),""),'08_الطلب المفقود'!$K$5:$K$1000) -> 0 | G15: =ROUND(($C15*0.4)+($F15*0.4)+(IFERROR($E15/$D15,0)*100*0.2),1) -> 6.6
A16: TD-FLT-0010 | B16: =IFERROR(INDEX('02_كتالوج القطع'!$C$4:$C$200,MATCH($A16,'02_كتالوج القطع'!$A$4:$A$200,0)),"-") -> فلتر زيت | C16: =SUMIF('07_سجل الطلبات'!$C$4:$C$1000,$A16,'07_سجل الطلبات'!$D$4:$D$1000) -> 14 | D16: =SUMIF('07_سجل الطلبات'!$C$4:$C$1000,$A16,'07_سجل الطلبات'!$H$4:$H$1000) -> 566.72 | E16: =SUMIF('07_سجل الطلبات'!$C$4:$C$1000,$A16,'07_سجل الطلبات'!$I$4:$I$1000) -> 184.8 | F16: =SUMIF('08_الطلب المفقود'!$C$5:$C$1000,IFERROR(INDEX('02_كتالوج القطع'!$B$4:$B$200,MATCH($A16,'02_كتالوج القطع'!$A$4:$A$200,0)),""),'08_الطلب المفقود'!$K$5:$K$1000) -> 0 | G16: =ROUND(($C16*0.4)+($F16*0.4)+(IFERROR($E16/$D16,0)*100*0.2),1) -> 12.1
A17: TD-BAT-0020 | B17: =IFERROR(INDEX('02_كتالوج القطع'!$C$4:$C$200,MATCH($A17,'02_كتالوج القطع'!$A$4:$A$200,0)),"-") -> بطارية 70 أمبير | C17: =SUMIF('07_سجل الطلبات'!$C$4:$C$1000,$A17,'07_سجل الطلبات'!$D$4:$D$1000) -> 1 | D17: =SUMIF('07_سجل الطلبات'!$C$4:$C$1000,$A17,'07_سجل الطلبات'!$H$4:$H$1000) -> 426.08 | E17: =SUMIF('07_سجل الطلبات'!$C$4:$C$1000,$A17,'07_سجل الطلبات'!$I$4:$I$1000) -> 85.504348 | F17: =SUMIF('08_الطلب المفقود'!$C$5:$C$1000,IFERROR(INDEX('02_كتالوج القطع'!$B$4:$B$200,MATCH($A17,'02_كتالوج القطع'!$A$4:$A$200,0)),""),'08_الطلب المفقود'!$K$5:$K$1000) -> 0 | G17: =ROUND(($C17*0.4)+($F17*0.4)+(IFERROR($E17/$D17,0)*100*0.2),1) -> 4.4
A18: TD-SUS-0031 | B18: =IFERROR(INDEX('02_كتالوج القطع'!$C$4:$C$200,MATCH($A18,'02_كتالوج القطع'!$A$4:$A$200,0)),"-") -> مساعد أمامي | C18: =SUMIF('07_سجل الطلبات'!$C$4:$C$1000,$A18,'07_سجل الطلبات'!$D$4:$D$1000) -> 2 | D18: =SUMIF('07_سجل الطلبات'!$C$4:$C$1000,$A18,'07_سجل الطلبات'!$H$4:$H$1000) -> 1055.7 | E18: =SUMIF('07_سجل الطلبات'!$C$4:$C$1000,$A18,'07_سجل الطلبات'!$I$4:$I$1000) -> 238 | F18: =SUMIF('08_الطلب المفقود'!$C$5:$C$1000,IFERROR(INDEX('02_كتالوج القطع'!$B$4:$B$200,MATCH($A18,'02_كتالوج القطع'!$A$4:$A$200,0)),""),'08_الطلب المفقود'!$K$5:$K$1000) -> 0 | G18: =ROUND(($C18*0.4)+($F18*0.4)+(IFERROR($E18/$D18,0)*100*0.2),1) -> 5.3
A19: TD-COL-0044 | B19: =IFERROR(INDEX('02_كتالوج القطع'!$C$4:$C$200,MATCH($A19,'02_كتالوج القطع'!$A$4:$A$200,0)),"-") -> ردياتير | C19: =SUMIF('07_سجل الطلبات'!$C$4:$C$1000,$A19,'07_سجل الطلبات'!$D$4:$D$1000) -> 1 | D19: =SUMIF('07_سجل الطلبات'!$C$4:$C$1000,$A19,'07_سجل الطلبات'!$H$4:$H$1000) -> 728.64 | E19: =SUMIF('07_سجل الطلبات'!$C$4:$C$1000,$A19,'07_سجل الطلبات'!$I$4:$I$1000) -> 153.6 | F19: =SUMIF('08_الطلب المفقود'!$C$5:$C$1000,IFERROR(INDEX('02_كتالوج القطع'!$B$4:$B$200,MATCH($A19,'02_كتالوج القطع'!$A$4:$A$200,0)),""),'08_الطلب المفقود'!$K$5:$K$1000) -> 0 | G19: =ROUND(($C19*0.4)+($F19*0.4)+(IFERROR($E19/$D19,0)*100*0.2),1) -> 4.6
A20: TD-ELC-0055 | B20: =IFERROR(INDEX('02_كتالوج القطع'!$C$4:$C$200,MATCH($A20,'02_كتالوج القطع'!$A$4:$A$200,0)),"-") -> دينمو تشغيل (سلف) | C20: =SUMIF('07_سجل الطلبات'!$C$4:$C$1000,$A20,'07_سجل الطلبات'!$D$4:$D$1000) -> 1 | D20: =SUMIF('07_سجل الطلبات'!$C$4:$C$1000,$A20,'07_سجل الطلبات'!$H$4:$H$1000) -> 627.9 | E20: =SUMIF('07_سجل الطلبات'!$C$4:$C$1000,$A20,'07_سجل الطلبات'!$I$4:$I$1000) -> 156 | F20: =SUMIF('08_الطلب المفقود'!$C$5:$C$1000,IFERROR(INDEX('02_كتالوج القطع'!$B$4:$B$200,MATCH($A20,'02_كتالوج القطع'!$A$4:$A$200,0)),""),'08_الطلب المفقود'!$K$5:$K$1000) -> 0 | G20: =ROUND(($C20*0.4)+($F20*0.4)+(IFERROR($E20/$D20,0)*100*0.2),1) -> 5.4
A21: TD-BDY-0066 | B21: =IFERROR(INDEX('02_كتالوج القطع'!$C$4:$C$200,MATCH($A21,'02_كتالوج القطع'!$A$4:$A$200,0)),"-") -> صدام أمامي | C21: =SUMIF('07_سجل الطلبات'!$C$4:$C$1000,$A21,'07_سجل الطلبات'!$D$4:$D$1000) -> 1 | D21: =SUMIF('07_سجل الطلبات'!$C$4:$C$1000,$A21,'07_سجل الطلبات'!$H$4:$H$1000) -> 912.13 | E21: =SUMIF('07_سجل الطلبات'!$C$4:$C$1000,$A21,'07_سجل الطلبات'!$I$4:$I$1000) -> 173.15652 | F21: =SUMIF('08_الطلب المفقود'!$C$5:$C$1000,IFERROR(INDEX('02_كتالوج القطع'!$B$4:$B$200,MATCH($A21,'02_كتالوج القطع'!$A$4:$A$200,0)),""),'08_الطلب المفقود'!$K$5:$K$1000) -> 0 | G21: =ROUND(($C21*0.4)+($F21*0.4)+(IFERROR($E21/$D21,0)*100*0.2),1) -> 4.2
A23: درجة أولوية التصنيع = (الكمية المباعة×0.4) + (الطلب المفقود×0.4) + (نسبة الربح×100×0.2). الأعلى درجة = أول ما تصنّعه.
A25: ثالثاً: المبيعات حسب المدينة
A26: المدينة | B26: عدد الطلبات | C26: إجمالي المبيعات | D26: نسبة الالتزام بالوعد
A27: الرياض | B27: =COUNTIF('07_سجل الطلبات'!$E$4:$E$1000,$A27) -> 4 | C27: =SUMIF('07_سجل الطلبات'!$E$4:$E$1000,$A27,'07_سجل الطلبات'!$H$4:$H$1000) -> 2111.53 | D27: =IFERROR(COUNTIFS('07_سجل الطلبات'!$E$4:$E$1000,$A27,'07_سجل الطلبات'!$L$4:$L$1000,"نعم")/$B27,0) -> 1
A28: الخرج | B28: =COUNTIF('07_سجل الطلبات'!$E$4:$E$1000,$A28) -> 0 | C28: =SUMIF('07_سجل الطلبات'!$E$4:$E$1000,$A28,'07_سجل الطلبات'!$H$4:$H$1000) -> 0 | D28: =IFERROR(COUNTIFS('07_سجل الطلبات'!$E$4:$E$1000,$A28,'07_سجل الطلبات'!$L$4:$L$1000,"نعم")/$B28,0) -> 0
A29: القصيم | B29: =COUNTIF('07_سجل الطلبات'!$E$4:$E$1000,$A29) -> 1 | C29: =SUMIF('07_سجل الطلبات'!$E$4:$E$1000,$A29,'07_سجل الطلبات'!$H$4:$H$1000) -> 600.3 | D29: =IFERROR(COUNTIFS('07_سجل الطلبات'!$E$4:$E$1000,$A29,'07_سجل الطلبات'!$L$4:$L$1000,"نعم")/$B29,0) -> 1
A30: جدة | B30: =COUNTIF('07_سجل الطلبات'!$E$4:$E$1000,$A30) -> 2 | C30: =SUMIF('07_سجل الطلبات'!$E$4:$E$1000,$A30,'07_سجل الطلبات'!$H$4:$H$1000) -> 789.82 | D30: =IFERROR(COUNTIFS('07_سجل الطلبات'!$E$4:$E$1000,$A30,'07_سجل الطلبات'!$L$4:$L$1000,"نعم")/$B30,0) -> 0.5
A31: مكة المكرمة | B31: =COUNTIF('07_سجل الطلبات'!$E$4:$E$1000,$A31) -> 1 | C31: =SUMIF('07_سجل الطلبات'!$E$4:$E$1000,$A31,'07_سجل الطلبات'!$H$4:$H$1000) -> 912.13 | D31: =IFERROR(COUNTIFS('07_سجل الطلبات'!$E$4:$E$1000,$A31,'07_سجل الطلبات'!$L$4:$L$1000,"نعم")/$B31,0) -> 1
A32: المدينة المنورة | B32: =COUNTIF('07_سجل الطلبات'!$E$4:$E$1000,$A32) -> 0 | C32: =SUMIF('07_سجل الطلبات'!$E$4:$E$1000,$A32,'07_سجل الطلبات'!$H$4:$H$1000) -> 0 | D32: =IFERROR(COUNTIFS('07_سجل الطلبات'!$E$4:$E$1000,$A32,'07_سجل الطلبات'!$L$4:$L$1000,"نعم")/$B32,0) -> 0
A33: الدمام | B33: =COUNTIF('07_سجل الطلبات'!$E$4:$E$1000,$A33) -> 1 | C33: =SUMIF('07_سجل الطلبات'!$E$4:$E$1000,$A33,'07_سجل الطلبات'!$H$4:$H$1000) -> 426.08 | D33: =IFERROR(COUNTIFS('07_سجل الطلبات'!$E$4:$E$1000,$A33,'07_سجل الطلبات'!$L$4:$L$1000,"نعم")/$B33,0) -> 0
A34: أبها | B34: =COUNTIF('07_سجل الطلبات'!$E$4:$E$1000,$A34) -> 1 | C34: =SUMIF('07_سجل الطلبات'!$E$4:$E$1000,$A34,'07_سجل الطلبات'!$H$4:$H$1000) -> 1055.7 | D34: =IFERROR(COUNTIFS('07_سجل الطلبات'!$E$4:$E$1000,$A34,'07_سجل الطلبات'!$L$4:$L$1000,"نعم")/$B34,0) -> 0
A35: جازان | B35: =COUNTIF('07_سجل الطلبات'!$E$4:$E$1000,$A35) -> 0 | C35: =SUMIF('07_سجل الطلبات'!$E$4:$E$1000,$A35,'07_سجل الطلبات'!$H$4:$H$1000) -> 0 | D35: =IFERROR(COUNTIFS('07_سجل الطلبات'!$E$4:$E$1000,$A35,'07_سجل الطلبات'!$L$4:$L$1000,"نعم")/$B35,0) -> 0
A36: تبوك | B36: =COUNTIF('07_سجل الطلبات'!$E$4:$E$1000,$A36) -> 0 | C36: =SUMIF('07_سجل الطلبات'!$E$4:$E$1000,$A36,'07_سجل الطلبات'!$H$4:$H$1000) -> 0 | D36: =IFERROR(COUNTIFS('07_سجل الطلبات'!$E$4:$E$1000,$A36,'07_سجل الطلبات'!$L$4:$L$1000,"نعم")/$B36,0) -> 0
A37: حائل | B37: =COUNTIF('07_سجل الطلبات'!$E$4:$E$1000,$A37) -> 0 | C37: =SUMIF('07_سجل الطلبات'!$E$4:$E$1000,$A37,'07_سجل الطلبات'!$H$4:$H$1000) -> 0 | D37: =IFERROR(COUNTIFS('07_سجل الطلبات'!$E$4:$E$1000,$A37,'07_سجل الطلبات'!$L$4:$L$1000,"نعم")/$B37,0) -> 0
A40: رابعاً: أعلى فرص التصنيع من الطلب المفقود (قطع لا نبيعها اليوم)
A41: رقم OEM | B41: الوصف | C41: الماركة / الموديل | D41: الطلب المقدّر شهرياً | E41: إجمالي مرات البحث | F41: درجة الفرصة
A42: 04466-33210 | B42: فحمات خلفية كامري 2022 | C42: تويوتا كامري 2022 | D42: =SUMIF('08_الطلب المفقود'!$C$5:$C$1000,$A42,'08_الطلب المفقود'!$K$5:$K$1000) -> 30 | E42: =SUMIF('08_الطلب المفقود'!$C$5:$C$1000,$A42,'08_الطلب المفقود'!$H$5:$H$1000) -> 22 | F42: =ROUND($D42*12*0.7+$E42*0.3,0) -> 259
A43: 04465-0K420 | B43: فحمات فرامل هايلكس | C43: تويوتا هايلكس 2020 | D43: =SUMIF('08_الطلب المفقود'!$C$5:$C$1000,$A43,'08_الطلب المفقود'!$K$5:$K$1000) -> 25 | E43: =SUMIF('08_الطلب المفقود'!$C$5:$C$1000,$A43,'08_الطلب المفقود'!$H$5:$H$1000) -> 19 | F43: =ROUND($D43*12*0.7+$E43*0.3,0) -> 216
A44: 48510-0K680 | B44: مساعد امامي هايلكس | C44: تويوتا هايلكس 2021 | D44: =SUMIF('08_الطلب المفقود'!$C$5:$C$1000,$A44,'08_الطلب المفقود'!$K$5:$K$1000) -> 20 | E44: =SUMIF('08_الطلب المفقود'!$C$5:$C$1000,$A44,'08_الطلب المفقود'!$H$5:$H$1000) -> 16 | F44: =ROUND($D44*12*0.7+$E44*0.3,0) -> 173
A45: 48531-0K600 | B45: مساعد خلفي هايلكس 2019 | C45: تويوتا هايلكس 2019 | D45: =SUMIF('08_الطلب المفقود'!$C$5:$C$1000,$A45,'08_الطلب المفقود'!$K$5:$K$1000) -> 18 | E45: =SUMIF('08_الطلب المفقود'!$C$5:$C$1000,$A45,'08_الطلب المفقود'!$H$5:$H$1000) -> 14 | F45: =ROUND($D45*12*0.7+$E45*0.3,0) -> 155
A46: 31111-2H000 | B46: طرمبة بنزين النترا | C46: هيونداي النترا 2020 | D46: =SUMIF('08_الطلب المفقود'!$C$5:$C$1000,$A46,'08_الطلب المفقود'!$K$5:$K$1000) -> 15 | E46: =SUMIF('08_الطلب المفقود'!$C$5:$C$1000,$A46,'08_الطلب المفقود'!$H$5:$H$1000) -> 11 | F46: =ROUND($D46*12*0.7+$E46*0.3,0) -> 129
A47: 88320-60800 | B47: كمبروسر مكيف لاندكروزر | C47: تويوتا لاندكروزر 2018 | D47: =SUMIF('08_الطلب المفقود'!$C$5:$C$1000,$A47,'08_الطلب المفقود'!$K$5:$K$1000) -> 12 | E47: =SUMIF('08_الطلب المفقود'!$C$5:$C$1000,$A47,'08_الطلب المفقود'!$H$5:$H$1000) -> 9 | F47: =ROUND($D47*12*0.7+$E47*0.3,0) -> 104
...

Sheet 10_أجور التركيب
A1: أجور التركيب في المركز — أساس خصم الـ 10%
A3: كود القطعة (SKU) | B3: اسم القطعة | C3: ساعات العمل المعيارية | D3: سعر الساعة | E3: أجرة التركيب قبل الخصم | F3: قيمة الخصم | G3: أجرة التركيب بعد الخصم | H3: إجمالي (قطعة + تركيب) | I3: توفير العميل
A4: TD-BRK-0001 | B4: =IFERROR(INDEX('02_كتالوج القطع'!$C$4:$C$200,MATCH($A4,'02_كتالوج القطع'!$A$4:$A$200,0)),"-") -> فحمات فرامل أمامية | C4: 1 | D4: =01_الإعدادات!$B$12 -> 120 | E4: =$C4*$D4 -> 120 | F4: =$E4*01_الإعدادات!$B$13 -> 12 | G4: =$E4-$F4 -> 108 | H4: =IFERROR(INDEX('04_التسعير والمخزون'!$G$4:$G$200,MATCH($A4,'04_التسعير والمخزون'!$A$4:$A$200,0)),0)+$G4 -> 434.025 | I4: =$F4 -> 12
A5: TD-BRK-0002 | B5: =IFERROR(INDEX('02_كتالوج القطع'!$C$4:$C$200,MATCH($A5,'02_كتالوج القطع'!$A$4:$A$200,0)),"-") -> فحمات فرامل أمامية | C5: 1 | D5: =01_الإعدادات!$B$12 -> 120 | E5: =$C5*$D5 -> 120 | F5: =$E5*01_الإعدادات!$B$13 -> 12 | G5: =$E5-$F5 -> 108 | H5: =IFERROR(INDEX('04_التسعير والمخزون'!$G$4:$G$200,MATCH($A5,'04_التسعير والمخزون'!$A$4:$A$200,0)),0)+$G5 -> 308.1 | I5: =$F5 -> 12
A6: TD-FLT-0010 | B6: =IFERROR(INDEX('02_كتالوج القطع'!$C$4:$C$200,MATCH($A6,'02_كتالوج القطع'!$A$4:$A$200,0)),"-") -> فلتر زيت | C6: 0.5 | D6: =01_الإعدادات!$B$12 -> 120 | E6: =$C6*$D6 -> 60 | F6: =$E6*01_الإعدادات!$B$13 -> 6 | G6: =$E6-$F6 -> 54 | H6: =IFERROR(INDEX('04_التسعير والمخزون'!$G$4:$G$200,MATCH($A6,'04_التسعير والمخزون'!$A$4:$A$200,0)),0)+$G6 -> 94.48 | I6: =$F6 -> 6
A7: TD-BAT-0020 | B7: =IFERROR(INDEX('02_كتالوج القطع'!$C$4:$C$200,MATCH($A7,'02_كتالوج القطع'!$A$4:$A$200,0)),"-") -> بطارية 70 أمبير | C7: 0.4 | D7: =01_الإعدادات!$B$12 -> 120 | E7: =$C7*$D7 -> 48 | F7: =$E7*01_الإعدادات!$B$13 -> 4.8 | G7: =$E7-$F7 -> 43.2 | H7: =IFERROR(INDEX('04_التسعير والمخزون'!$G$4:$G$200,MATCH($A7,'04_التسعير والمخزون'!$A$4:$A$200,0)),0)+$G7 -> 469.275 | I7: =$F7 -> 4.8
A8: TD-SUS-0031 | B8: =IFERROR(INDEX('02_كتالوج القطع'!$C$4:$C$200,MATCH($A8,'02_كتالوج القطع'!$A$4:$A$200,0)),"-") -> مساعد أمامي | C8: 1.5 | D8: =01_الإعدادات!$B$12 -> 120 | E8: =$C8*$D8 -> 180 | F8: =$E8*01_الإعدادات!$B$13 -> 18 | G8: =$E8-$F8 -> 162 | H8: =IFERROR(INDEX('04_التسعير والمخزون'!$G$4:$G$200,MATCH($A8,'04_التسعير والمخزون'!$A$4:$A$200,0)),0)+$G8 -> 689.85 | I8: =$F8 -> 18
A9: TD-COL-0044 | B9: =IFERROR(INDEX('02_كتالوج القطع'!$C$4:$C$200,MATCH($A9,'02_كتالوج القطع'!$A$4:$A$200,0)),"-") -> ردياتير | C9: 2.5 | D9: =01_الإعدادات!$B$12 -> 120 | E9: =$C9*$D9 -> 300 | F9: =$E9*01_الإعدادات!$B$13 -> 30 | G9: =$E9-$F9 -> 270 | H9: =IFERROR(INDEX('04_التسعير والمخزون'!$G$4:$G$200,MATCH($A9,'04_التسعير والمخزون'!$A$4:$A$200,0)),0)+$G9 -> 998.64 | I9: =$F9 -> 30
A10: TD-ELC-0055 | B10: =IFERROR(INDEX('02_كتالوج القطع'!$C$4:$C$200,MATCH($A10,'02_كتالوج القطع'!$A$4:$A$200,0)),"-") -> دينمو تشغيل (سلف) | C10: 2 | D10: =01_الإعدادات!$B$12 -> 120 | E10: =$C10*$D10 -> 240 | F10: =$E10*01_الإعدادات!$B$13 -> 24 | G10: =$E10-$F10 -> 216 | H10: =IFERROR(INDEX('04_التسعير والمخزون'!$G$4:$G$200,MATCH($A10,'04_التسعير والمخزون'!$A$4:$A$200,0)),0)+$G10 -> 843.9 | I10: =$F10 -> 24
A11: TD-BDY-0066 | B11: =IFERROR(INDEX('02_كتالوج القطع'!$C$4:$C$200,MATCH($A11,'02_كتالوج القطع'!$A$4:$A$200,0)),"-") -> صدام أمامي | C11: 3 | D11: =01_الإعدادات!$B$12 -> 120 | E11: =$C11*$D11 -> 360 | F11: =$E11*01_الإعدادات!$B$13 -> 36 | G11: =$E11-$F11 -> 324 | H11: =IFERROR(INDEX('04_التسعير والمخزون'!$G$4:$G$200,MATCH($A11,'04_التسعير والمخزون'!$A$4:$A$200,0)),0)+$G11 -> 1236.64 | I11: =$F11 -> 36
A13: القاعدة: من يشتري القطعة من الموقع ويختار التركيب لدينا يحصل على خصم 10% من أجرة اليد. غيّر النسبة من ورقة 01 خلية B13.

Sheet 11_خريطة الرسم
A1: خريطة الرسم التفاعلي — ربط مناطق السيارة بالقطع
A2: هذه الورقة يقرأها المبرمج لرسم النقاط التفاعلية على مخطط السيارة.
A4: معرّف المنطقة | B4: اسم المنطقة (عربي) | C4: الطبقة/التصنيف | D4: إحداثي X | E4: إحداثي Y | F4: رقم الاستدعاء | G4: كود القطعة (SKU) | H4: رقم OEM | I4: ملاحظة
A5: ZN-ENG | B5: المحرك والتبريد | C5: ميكانيكا | D5: 140 | E5: 195 | F5: 1 | G5: TD-COL-0044 | H5: 16400-0P260 | I5: ردياتير
A6: ZN-ENG | B6: المحرك والتبريد | C6: ميكانيكا | D6: 140 | E6: 195 | F6: 2 | G6: TD-FLT-0010 | H6: 90915-YZZD4 | I6: فلتر زيت
A7: ZN-BRF | B7: الفرامل والعفشة الأمامية | C7: عفشة وفرامل | D7: 200 | E7: 245 | F7: 1 | G7: TD-BRK-0001 | H7: 04465-33471 | I7: فحمات أمامية وكالة
A8: ZN-BRF | B8: الفرامل والعفشة الأمامية | C8: عفشة وفرامل | D8: 200 | E8: 245 | F8: 2 | G8: TD-BRK-0002 | H8: AD-0451 | I8: فحمات أمامية بديل
A9: ZN-BRF | B9: الفرامل والعفشة الأمامية | C9: عفشة وفرامل | D9: 200 | E9: 245 | F9: 3 | G9: TD-SUS-0031 | H9: 48510-0K120 | I9: مساعد أمامي
A10: ZN-ELC | B10: الكهرباء والبطارية | C10: كهرباء | D10: 250 | E10: 175 | F10: 1 | G10: TD-BAT-0020 | H10: AGM-70AH | I10: بطارية
A11: ZN-ELC | B11: الكهرباء والبطارية | C11: كهرباء | D11: 250 | E11: 175 | F11: 2 | G11: TD-ELC-0055 | H11: 28100-0T030 | I11: دينمو تشغيل
A12: ZN-BDY | B12: البدي والصدامات | C12: بدي | D12: 735 | E12: 200 | F12: 1 | G12: TD-BDY-0066 | H12: 53101-06923 | I12: صدام أمامي
A14: الإحداثيات نسبية لمخطط SVG بمقاس 800×320. كل منطقة قد تحتوي عدة قطع — كررها بنفس معرّف المنطقة وغيّر رقم الاستدعاء.
A15: الطبقات المعتمدة: بدي · ميكانيكا · كهرباء · عفشة وفرامل · استهلاكية · أداء
